{
 "cells": [
  {
   "cell_type": "code",
   "execution_count": 1,
   "id": "bb66ac93",
   "metadata": {},
   "outputs": [],
   "source": [
    "import os\n",
    "from transformers import AutoTokenizer, AutoModel\n",
    "import torch"
   ]
  },
  {
   "cell_type": "code",
   "execution_count": 2,
   "id": "1d06ae21",
   "metadata": {},
   "outputs": [
    {
     "ename": "OSError",
     "evalue": "INSAIT/bgGPT is not a local folder and is not a valid model identifier listed on 'https://huggingface.co/models'\nIf this is a private repository, make sure to pass a token having permission to this repo either by logging in with `huggingface-cli login` or by passing `token=<your_token>`",
     "output_type": "error",
     "traceback": [
      "\u001b[1;31m---------------------------------------------------------------------------\u001b[0m",
      "\u001b[1;31mHTTPError\u001b[0m                                 Traceback (most recent call last)",
      "File \u001b[1;32m~\\anaconda3\\Lib\\site-packages\\huggingface_hub\\utils\\_http.py:406\u001b[0m, in \u001b[0;36mhf_raise_for_status\u001b[1;34m(response, endpoint_name)\u001b[0m\n\u001b[0;32m    405\u001b[0m \u001b[38;5;28;01mtry\u001b[39;00m:\n\u001b[1;32m--> 406\u001b[0m     response\u001b[38;5;241m.\u001b[39mraise_for_status()\n\u001b[0;32m    407\u001b[0m \u001b[38;5;28;01mexcept\u001b[39;00m HTTPError \u001b[38;5;28;01mas\u001b[39;00m e:\n",
      "File \u001b[1;32m~\\AppData\\Roaming\\Python\\Python311\\site-packages\\requests\\models.py:1024\u001b[0m, in \u001b[0;36mResponse.raise_for_status\u001b[1;34m(self)\u001b[0m\n\u001b[0;32m   1023\u001b[0m \u001b[38;5;28;01mif\u001b[39;00m http_error_msg:\n\u001b[1;32m-> 1024\u001b[0m     \u001b[38;5;28;01mraise\u001b[39;00m HTTPError(http_error_msg, response\u001b[38;5;241m=\u001b[39m\u001b[38;5;28mself\u001b[39m)\n",
      "\u001b[1;31mHTTPError\u001b[0m: 401 Client Error: Unauthorized for url: https://huggingface.co/INSAIT/bgGPT/resolve/main/tokenizer_config.json",
      "\nThe above exception was the direct cause of the following exception:\n",
      "\u001b[1;31mRepositoryNotFoundError\u001b[0m                   Traceback (most recent call last)",
      "File \u001b[1;32m~\\anaconda3\\Lib\\site-packages\\transformers\\utils\\hub.py:403\u001b[0m, in \u001b[0;36mcached_file\u001b[1;34m(path_or_repo_id, filename, cache_dir, force_download, resume_download, proxies, token, revision, local_files_only, subfolder, repo_type, user_agent, _raise_exceptions_for_gated_repo, _raise_exceptions_for_missing_entries, _raise_exceptions_for_connection_errors, _commit_hash, **deprecated_kwargs)\u001b[0m\n\u001b[0;32m    401\u001b[0m \u001b[38;5;28;01mtry\u001b[39;00m:\n\u001b[0;32m    402\u001b[0m     \u001b[38;5;66;03m# Load from URL or cache if already cached\u001b[39;00m\n\u001b[1;32m--> 403\u001b[0m     resolved_file \u001b[38;5;241m=\u001b[39m hf_hub_download(\n\u001b[0;32m    404\u001b[0m         path_or_repo_id,\n\u001b[0;32m    405\u001b[0m         filename,\n\u001b[0;32m    406\u001b[0m         subfolder\u001b[38;5;241m=\u001b[39m\u001b[38;5;28;01mNone\u001b[39;00m \u001b[38;5;28;01mif\u001b[39;00m \u001b[38;5;28mlen\u001b[39m(subfolder) \u001b[38;5;241m==\u001b[39m \u001b[38;5;241m0\u001b[39m \u001b[38;5;28;01melse\u001b[39;00m subfolder,\n\u001b[0;32m    407\u001b[0m         repo_type\u001b[38;5;241m=\u001b[39mrepo_type,\n\u001b[0;32m    408\u001b[0m         revision\u001b[38;5;241m=\u001b[39mrevision,\n\u001b[0;32m    409\u001b[0m         cache_dir\u001b[38;5;241m=\u001b[39mcache_dir,\n\u001b[0;32m    410\u001b[0m         user_agent\u001b[38;5;241m=\u001b[39muser_agent,\n\u001b[0;32m    411\u001b[0m         force_download\u001b[38;5;241m=\u001b[39mforce_download,\n\u001b[0;32m    412\u001b[0m         proxies\u001b[38;5;241m=\u001b[39mproxies,\n\u001b[0;32m    413\u001b[0m         resume_download\u001b[38;5;241m=\u001b[39mresume_download,\n\u001b[0;32m    414\u001b[0m         token\u001b[38;5;241m=\u001b[39mtoken,\n\u001b[0;32m    415\u001b[0m         local_files_only\u001b[38;5;241m=\u001b[39mlocal_files_only,\n\u001b[0;32m    416\u001b[0m     )\n\u001b[0;32m    417\u001b[0m \u001b[38;5;28;01mexcept\u001b[39;00m GatedRepoError \u001b[38;5;28;01mas\u001b[39;00m e:\n",
      "File \u001b[1;32m~\\anaconda3\\Lib\\site-packages\\huggingface_hub\\utils\\_validators.py:114\u001b[0m, in \u001b[0;36mvalidate_hf_hub_args.<locals>._inner_fn\u001b[1;34m(*args, **kwargs)\u001b[0m\n\u001b[0;32m    112\u001b[0m     kwargs \u001b[38;5;241m=\u001b[39m smoothly_deprecate_use_auth_token(fn_name\u001b[38;5;241m=\u001b[39mfn\u001b[38;5;241m.\u001b[39m\u001b[38;5;18m__name__\u001b[39m, has_token\u001b[38;5;241m=\u001b[39mhas_token, kwargs\u001b[38;5;241m=\u001b[39mkwargs)\n\u001b[1;32m--> 114\u001b[0m \u001b[38;5;28;01mreturn\u001b[39;00m fn(\u001b[38;5;241m*\u001b[39margs, \u001b[38;5;241m*\u001b[39m\u001b[38;5;241m*\u001b[39mkwargs)\n",
      "File \u001b[1;32m~\\anaconda3\\Lib\\site-packages\\huggingface_hub\\file_download.py:862\u001b[0m, in \u001b[0;36mhf_hub_download\u001b[1;34m(repo_id, filename, subfolder, repo_type, revision, library_name, library_version, cache_dir, local_dir, user_agent, force_download, proxies, etag_timeout, token, local_files_only, headers, endpoint, resume_download, force_filename, local_dir_use_symlinks)\u001b[0m\n\u001b[0;32m    861\u001b[0m \u001b[38;5;28;01melse\u001b[39;00m:\n\u001b[1;32m--> 862\u001b[0m     \u001b[38;5;28;01mreturn\u001b[39;00m _hf_hub_download_to_cache_dir(\n\u001b[0;32m    863\u001b[0m         \u001b[38;5;66;03m# Destination\u001b[39;00m\n\u001b[0;32m    864\u001b[0m         cache_dir\u001b[38;5;241m=\u001b[39mcache_dir,\n\u001b[0;32m    865\u001b[0m         \u001b[38;5;66;03m# File info\u001b[39;00m\n\u001b[0;32m    866\u001b[0m         repo_id\u001b[38;5;241m=\u001b[39mrepo_id,\n\u001b[0;32m    867\u001b[0m         filename\u001b[38;5;241m=\u001b[39mfilename,\n\u001b[0;32m    868\u001b[0m         repo_type\u001b[38;5;241m=\u001b[39mrepo_type,\n\u001b[0;32m    869\u001b[0m         revision\u001b[38;5;241m=\u001b[39mrevision,\n\u001b[0;32m    870\u001b[0m         \u001b[38;5;66;03m# HTTP info\u001b[39;00m\n\u001b[0;32m    871\u001b[0m         endpoint\u001b[38;5;241m=\u001b[39mendpoint,\n\u001b[0;32m    872\u001b[0m         etag_timeout\u001b[38;5;241m=\u001b[39metag_timeout,\n\u001b[0;32m    873\u001b[0m         headers\u001b[38;5;241m=\u001b[39mheaders,\n\u001b[0;32m    874\u001b[0m         proxies\u001b[38;5;241m=\u001b[39mproxies,\n\u001b[0;32m    875\u001b[0m         token\u001b[38;5;241m=\u001b[39mtoken,\n\u001b[0;32m    876\u001b[0m         \u001b[38;5;66;03m# Additional options\u001b[39;00m\n\u001b[0;32m    877\u001b[0m         local_files_only\u001b[38;5;241m=\u001b[39mlocal_files_only,\n\u001b[0;32m    878\u001b[0m         force_download\u001b[38;5;241m=\u001b[39mforce_download,\n\u001b[0;32m    879\u001b[0m     )\n",
      "File \u001b[1;32m~\\anaconda3\\Lib\\site-packages\\huggingface_hub\\file_download.py:969\u001b[0m, in \u001b[0;36m_hf_hub_download_to_cache_dir\u001b[1;34m(cache_dir, repo_id, filename, repo_type, revision, endpoint, etag_timeout, headers, proxies, token, local_files_only, force_download)\u001b[0m\n\u001b[0;32m    968\u001b[0m     \u001b[38;5;66;03m# Otherwise, raise appropriate error\u001b[39;00m\n\u001b[1;32m--> 969\u001b[0m     _raise_on_head_call_error(head_call_error, force_download, local_files_only)\n\u001b[0;32m    971\u001b[0m \u001b[38;5;66;03m# From now on, etag, commit_hash, url and size are not None.\u001b[39;00m\n",
      "File \u001b[1;32m~\\anaconda3\\Lib\\site-packages\\huggingface_hub\\file_download.py:1484\u001b[0m, in \u001b[0;36m_raise_on_head_call_error\u001b[1;34m(head_call_error, force_download, local_files_only)\u001b[0m\n\u001b[0;32m   1482\u001b[0m \u001b[38;5;28;01melif\u001b[39;00m \u001b[38;5;28misinstance\u001b[39m(head_call_error, RepositoryNotFoundError) \u001b[38;5;129;01mor\u001b[39;00m \u001b[38;5;28misinstance\u001b[39m(head_call_error, GatedRepoError):\n\u001b[0;32m   1483\u001b[0m     \u001b[38;5;66;03m# Repo not found or gated => let's raise the actual error\u001b[39;00m\n\u001b[1;32m-> 1484\u001b[0m     \u001b[38;5;28;01mraise\u001b[39;00m head_call_error\n\u001b[0;32m   1485\u001b[0m \u001b[38;5;28;01melse\u001b[39;00m:\n\u001b[0;32m   1486\u001b[0m     \u001b[38;5;66;03m# Otherwise: most likely a connection issue or Hub downtime => let's warn the user\u001b[39;00m\n",
      "File \u001b[1;32m~\\anaconda3\\Lib\\site-packages\\huggingface_hub\\file_download.py:1376\u001b[0m, in \u001b[0;36m_get_metadata_or_catch_error\u001b[1;34m(repo_id, filename, repo_type, revision, endpoint, proxies, etag_timeout, headers, token, local_files_only, relative_filename, storage_folder)\u001b[0m\n\u001b[0;32m   1375\u001b[0m \u001b[38;5;28;01mtry\u001b[39;00m:\n\u001b[1;32m-> 1376\u001b[0m     metadata \u001b[38;5;241m=\u001b[39m get_hf_file_metadata(\n\u001b[0;32m   1377\u001b[0m         url\u001b[38;5;241m=\u001b[39murl, proxies\u001b[38;5;241m=\u001b[39mproxies, timeout\u001b[38;5;241m=\u001b[39metag_timeout, headers\u001b[38;5;241m=\u001b[39mheaders, token\u001b[38;5;241m=\u001b[39mtoken\n\u001b[0;32m   1378\u001b[0m     )\n\u001b[0;32m   1379\u001b[0m \u001b[38;5;28;01mexcept\u001b[39;00m EntryNotFoundError \u001b[38;5;28;01mas\u001b[39;00m http_error:\n",
      "File \u001b[1;32m~\\anaconda3\\Lib\\site-packages\\huggingface_hub\\utils\\_validators.py:114\u001b[0m, in \u001b[0;36mvalidate_hf_hub_args.<locals>._inner_fn\u001b[1;34m(*args, **kwargs)\u001b[0m\n\u001b[0;32m    112\u001b[0m     kwargs \u001b[38;5;241m=\u001b[39m smoothly_deprecate_use_auth_token(fn_name\u001b[38;5;241m=\u001b[39mfn\u001b[38;5;241m.\u001b[39m\u001b[38;5;18m__name__\u001b[39m, has_token\u001b[38;5;241m=\u001b[39mhas_token, kwargs\u001b[38;5;241m=\u001b[39mkwargs)\n\u001b[1;32m--> 114\u001b[0m \u001b[38;5;28;01mreturn\u001b[39;00m fn(\u001b[38;5;241m*\u001b[39margs, \u001b[38;5;241m*\u001b[39m\u001b[38;5;241m*\u001b[39mkwargs)\n",
      "File \u001b[1;32m~\\anaconda3\\Lib\\site-packages\\huggingface_hub\\file_download.py:1296\u001b[0m, in \u001b[0;36mget_hf_file_metadata\u001b[1;34m(url, token, proxies, timeout, library_name, library_version, user_agent, headers)\u001b[0m\n\u001b[0;32m   1295\u001b[0m \u001b[38;5;66;03m# Retrieve metadata\u001b[39;00m\n\u001b[1;32m-> 1296\u001b[0m r \u001b[38;5;241m=\u001b[39m _request_wrapper(\n\u001b[0;32m   1297\u001b[0m     method\u001b[38;5;241m=\u001b[39m\u001b[38;5;124m\"\u001b[39m\u001b[38;5;124mHEAD\u001b[39m\u001b[38;5;124m\"\u001b[39m,\n\u001b[0;32m   1298\u001b[0m     url\u001b[38;5;241m=\u001b[39murl,\n\u001b[0;32m   1299\u001b[0m     headers\u001b[38;5;241m=\u001b[39mheaders,\n\u001b[0;32m   1300\u001b[0m     allow_redirects\u001b[38;5;241m=\u001b[39m\u001b[38;5;28;01mFalse\u001b[39;00m,\n\u001b[0;32m   1301\u001b[0m     follow_relative_redirects\u001b[38;5;241m=\u001b[39m\u001b[38;5;28;01mTrue\u001b[39;00m,\n\u001b[0;32m   1302\u001b[0m     proxies\u001b[38;5;241m=\u001b[39mproxies,\n\u001b[0;32m   1303\u001b[0m     timeout\u001b[38;5;241m=\u001b[39mtimeout,\n\u001b[0;32m   1304\u001b[0m )\n\u001b[0;32m   1305\u001b[0m hf_raise_for_status(r)\n",
      "File \u001b[1;32m~\\anaconda3\\Lib\\site-packages\\huggingface_hub\\file_download.py:277\u001b[0m, in \u001b[0;36m_request_wrapper\u001b[1;34m(method, url, follow_relative_redirects, **params)\u001b[0m\n\u001b[0;32m    276\u001b[0m \u001b[38;5;28;01mif\u001b[39;00m follow_relative_redirects:\n\u001b[1;32m--> 277\u001b[0m     response \u001b[38;5;241m=\u001b[39m _request_wrapper(\n\u001b[0;32m    278\u001b[0m         method\u001b[38;5;241m=\u001b[39mmethod,\n\u001b[0;32m    279\u001b[0m         url\u001b[38;5;241m=\u001b[39murl,\n\u001b[0;32m    280\u001b[0m         follow_relative_redirects\u001b[38;5;241m=\u001b[39m\u001b[38;5;28;01mFalse\u001b[39;00m,\n\u001b[0;32m    281\u001b[0m         \u001b[38;5;241m*\u001b[39m\u001b[38;5;241m*\u001b[39mparams,\n\u001b[0;32m    282\u001b[0m     )\n\u001b[0;32m    284\u001b[0m     \u001b[38;5;66;03m# If redirection, we redirect only relative paths.\u001b[39;00m\n\u001b[0;32m    285\u001b[0m     \u001b[38;5;66;03m# This is useful in case of a renamed repository.\u001b[39;00m\n",
      "File \u001b[1;32m~\\anaconda3\\Lib\\site-packages\\huggingface_hub\\file_download.py:301\u001b[0m, in \u001b[0;36m_request_wrapper\u001b[1;34m(method, url, follow_relative_redirects, **params)\u001b[0m\n\u001b[0;32m    300\u001b[0m response \u001b[38;5;241m=\u001b[39m get_session()\u001b[38;5;241m.\u001b[39mrequest(method\u001b[38;5;241m=\u001b[39mmethod, url\u001b[38;5;241m=\u001b[39murl, \u001b[38;5;241m*\u001b[39m\u001b[38;5;241m*\u001b[39mparams)\n\u001b[1;32m--> 301\u001b[0m hf_raise_for_status(response)\n\u001b[0;32m    302\u001b[0m \u001b[38;5;28;01mreturn\u001b[39;00m response\n",
      "File \u001b[1;32m~\\anaconda3\\Lib\\site-packages\\huggingface_hub\\utils\\_http.py:454\u001b[0m, in \u001b[0;36mhf_raise_for_status\u001b[1;34m(response, endpoint_name)\u001b[0m\n\u001b[0;32m    446\u001b[0m     message \u001b[38;5;241m=\u001b[39m (\n\u001b[0;32m    447\u001b[0m         \u001b[38;5;124mf\u001b[39m\u001b[38;5;124m\"\u001b[39m\u001b[38;5;132;01m{\u001b[39;00mresponse\u001b[38;5;241m.\u001b[39mstatus_code\u001b[38;5;132;01m}\u001b[39;00m\u001b[38;5;124m Client Error.\u001b[39m\u001b[38;5;124m\"\u001b[39m\n\u001b[0;32m    448\u001b[0m         \u001b[38;5;241m+\u001b[39m \u001b[38;5;124m\"\u001b[39m\u001b[38;5;130;01m\\n\u001b[39;00m\u001b[38;5;130;01m\\n\u001b[39;00m\u001b[38;5;124m\"\u001b[39m\n\u001b[1;32m   (...)\u001b[0m\n\u001b[0;32m    452\u001b[0m         \u001b[38;5;124m\"\u001b[39m\u001b[38;5;124m make sure you are authenticated.\u001b[39m\u001b[38;5;124m\"\u001b[39m\n\u001b[0;32m    453\u001b[0m     )\n\u001b[1;32m--> 454\u001b[0m     \u001b[38;5;28;01mraise\u001b[39;00m _format(RepositoryNotFoundError, message, response) \u001b[38;5;28;01mfrom\u001b[39;00m \u001b[38;5;21;01me\u001b[39;00m\n\u001b[0;32m    456\u001b[0m \u001b[38;5;28;01melif\u001b[39;00m response\u001b[38;5;241m.\u001b[39mstatus_code \u001b[38;5;241m==\u001b[39m \u001b[38;5;241m400\u001b[39m:\n",
      "\u001b[1;31mRepositoryNotFoundError\u001b[0m: 401 Client Error. (Request ID: Root=1-675f2441-6dcf8ad068e7f366090ee103;b795e277-3f33-4f3a-8c24-93dc03e6071f)\n\nRepository Not Found for url: https://huggingface.co/INSAIT/bgGPT/resolve/main/tokenizer_config.json.\nPlease make sure you specified the correct `repo_id` and `repo_type`.\nIf you are trying to access a private or gated repo, make sure you are authenticated.\nInvalid username or password.",
      "\nThe above exception was the direct cause of the following exception:\n",
      "\u001b[1;31mOSError\u001b[0m                                   Traceback (most recent call last)",
      "Cell \u001b[1;32mIn[2], line 2\u001b[0m\n\u001b[0;32m      1\u001b[0m \u001b[38;5;66;03m# Зареждане на токенизатора и модела\u001b[39;00m\n\u001b[1;32m----> 2\u001b[0m tokenizer \u001b[38;5;241m=\u001b[39m AutoTokenizer\u001b[38;5;241m.\u001b[39mfrom_pretrained(\u001b[38;5;124m\"\u001b[39m\u001b[38;5;124mINSAIT/bgGPT\u001b[39m\u001b[38;5;124m\"\u001b[39m)\n\u001b[0;32m      3\u001b[0m model \u001b[38;5;241m=\u001b[39m AutoModel\u001b[38;5;241m.\u001b[39mfrom_pretrained(\u001b[38;5;124m\"\u001b[39m\u001b[38;5;124mINSAIT/bgGPT\u001b[39m\u001b[38;5;124m\"\u001b[39m)\n",
      "File \u001b[1;32m~\\anaconda3\\Lib\\site-packages\\transformers\\models\\auto\\tokenization_auto.py:857\u001b[0m, in \u001b[0;36mAutoTokenizer.from_pretrained\u001b[1;34m(cls, pretrained_model_name_or_path, *inputs, **kwargs)\u001b[0m\n\u001b[0;32m    854\u001b[0m     \u001b[38;5;28;01mreturn\u001b[39;00m tokenizer_class\u001b[38;5;241m.\u001b[39mfrom_pretrained(pretrained_model_name_or_path, \u001b[38;5;241m*\u001b[39minputs, \u001b[38;5;241m*\u001b[39m\u001b[38;5;241m*\u001b[39mkwargs)\n\u001b[0;32m    856\u001b[0m \u001b[38;5;66;03m# Next, let's try to use the tokenizer_config file to get the tokenizer class.\u001b[39;00m\n\u001b[1;32m--> 857\u001b[0m tokenizer_config \u001b[38;5;241m=\u001b[39m get_tokenizer_config(pretrained_model_name_or_path, \u001b[38;5;241m*\u001b[39m\u001b[38;5;241m*\u001b[39mkwargs)\n\u001b[0;32m    858\u001b[0m \u001b[38;5;28;01mif\u001b[39;00m \u001b[38;5;124m\"\u001b[39m\u001b[38;5;124m_commit_hash\u001b[39m\u001b[38;5;124m\"\u001b[39m \u001b[38;5;129;01min\u001b[39;00m tokenizer_config:\n\u001b[0;32m    859\u001b[0m     kwargs[\u001b[38;5;124m\"\u001b[39m\u001b[38;5;124m_commit_hash\u001b[39m\u001b[38;5;124m\"\u001b[39m] \u001b[38;5;241m=\u001b[39m tokenizer_config[\u001b[38;5;124m\"\u001b[39m\u001b[38;5;124m_commit_hash\u001b[39m\u001b[38;5;124m\"\u001b[39m]\n",
      "File \u001b[1;32m~\\anaconda3\\Lib\\site-packages\\transformers\\models\\auto\\tokenization_auto.py:689\u001b[0m, in \u001b[0;36mget_tokenizer_config\u001b[1;34m(pretrained_model_name_or_path, cache_dir, force_download, resume_download, proxies, token, revision, local_files_only, subfolder, **kwargs)\u001b[0m\n\u001b[0;32m    686\u001b[0m     token \u001b[38;5;241m=\u001b[39m use_auth_token\n\u001b[0;32m    688\u001b[0m commit_hash \u001b[38;5;241m=\u001b[39m kwargs\u001b[38;5;241m.\u001b[39mget(\u001b[38;5;124m\"\u001b[39m\u001b[38;5;124m_commit_hash\u001b[39m\u001b[38;5;124m\"\u001b[39m, \u001b[38;5;28;01mNone\u001b[39;00m)\n\u001b[1;32m--> 689\u001b[0m resolved_config_file \u001b[38;5;241m=\u001b[39m cached_file(\n\u001b[0;32m    690\u001b[0m     pretrained_model_name_or_path,\n\u001b[0;32m    691\u001b[0m     TOKENIZER_CONFIG_FILE,\n\u001b[0;32m    692\u001b[0m     cache_dir\u001b[38;5;241m=\u001b[39mcache_dir,\n\u001b[0;32m    693\u001b[0m     force_download\u001b[38;5;241m=\u001b[39mforce_download,\n\u001b[0;32m    694\u001b[0m     resume_download\u001b[38;5;241m=\u001b[39mresume_download,\n\u001b[0;32m    695\u001b[0m     proxies\u001b[38;5;241m=\u001b[39mproxies,\n\u001b[0;32m    696\u001b[0m     token\u001b[38;5;241m=\u001b[39mtoken,\n\u001b[0;32m    697\u001b[0m     revision\u001b[38;5;241m=\u001b[39mrevision,\n\u001b[0;32m    698\u001b[0m     local_files_only\u001b[38;5;241m=\u001b[39mlocal_files_only,\n\u001b[0;32m    699\u001b[0m     subfolder\u001b[38;5;241m=\u001b[39msubfolder,\n\u001b[0;32m    700\u001b[0m     _raise_exceptions_for_gated_repo\u001b[38;5;241m=\u001b[39m\u001b[38;5;28;01mFalse\u001b[39;00m,\n\u001b[0;32m    701\u001b[0m     _raise_exceptions_for_missing_entries\u001b[38;5;241m=\u001b[39m\u001b[38;5;28;01mFalse\u001b[39;00m,\n\u001b[0;32m    702\u001b[0m     _raise_exceptions_for_connection_errors\u001b[38;5;241m=\u001b[39m\u001b[38;5;28;01mFalse\u001b[39;00m,\n\u001b[0;32m    703\u001b[0m     _commit_hash\u001b[38;5;241m=\u001b[39mcommit_hash,\n\u001b[0;32m    704\u001b[0m )\n\u001b[0;32m    705\u001b[0m \u001b[38;5;28;01mif\u001b[39;00m resolved_config_file \u001b[38;5;129;01mis\u001b[39;00m \u001b[38;5;28;01mNone\u001b[39;00m:\n\u001b[0;32m    706\u001b[0m     logger\u001b[38;5;241m.\u001b[39minfo(\u001b[38;5;124m\"\u001b[39m\u001b[38;5;124mCould not locate the tokenizer configuration file, will try to use the model config instead.\u001b[39m\u001b[38;5;124m\"\u001b[39m)\n",
      "File \u001b[1;32m~\\anaconda3\\Lib\\site-packages\\transformers\\utils\\hub.py:426\u001b[0m, in \u001b[0;36mcached_file\u001b[1;34m(path_or_repo_id, filename, cache_dir, force_download, resume_download, proxies, token, revision, local_files_only, subfolder, repo_type, user_agent, _raise_exceptions_for_gated_repo, _raise_exceptions_for_missing_entries, _raise_exceptions_for_connection_errors, _commit_hash, **deprecated_kwargs)\u001b[0m\n\u001b[0;32m    421\u001b[0m     \u001b[38;5;28;01mraise\u001b[39;00m \u001b[38;5;167;01mEnvironmentError\u001b[39;00m(\n\u001b[0;32m    422\u001b[0m         \u001b[38;5;124m\"\u001b[39m\u001b[38;5;124mYou are trying to access a gated repo.\u001b[39m\u001b[38;5;130;01m\\n\u001b[39;00m\u001b[38;5;124mMake sure to have access to it at \u001b[39m\u001b[38;5;124m\"\u001b[39m\n\u001b[0;32m    423\u001b[0m         \u001b[38;5;124mf\u001b[39m\u001b[38;5;124m\"\u001b[39m\u001b[38;5;124mhttps://huggingface.co/\u001b[39m\u001b[38;5;132;01m{\u001b[39;00mpath_or_repo_id\u001b[38;5;132;01m}\u001b[39;00m\u001b[38;5;124m.\u001b[39m\u001b[38;5;130;01m\\n\u001b[39;00m\u001b[38;5;132;01m{\u001b[39;00m\u001b[38;5;28mstr\u001b[39m(e)\u001b[38;5;132;01m}\u001b[39;00m\u001b[38;5;124m\"\u001b[39m\n\u001b[0;32m    424\u001b[0m     ) \u001b[38;5;28;01mfrom\u001b[39;00m \u001b[38;5;21;01me\u001b[39;00m\n\u001b[0;32m    425\u001b[0m \u001b[38;5;28;01mexcept\u001b[39;00m RepositoryNotFoundError \u001b[38;5;28;01mas\u001b[39;00m e:\n\u001b[1;32m--> 426\u001b[0m     \u001b[38;5;28;01mraise\u001b[39;00m \u001b[38;5;167;01mEnvironmentError\u001b[39;00m(\n\u001b[0;32m    427\u001b[0m         \u001b[38;5;124mf\u001b[39m\u001b[38;5;124m\"\u001b[39m\u001b[38;5;132;01m{\u001b[39;00mpath_or_repo_id\u001b[38;5;132;01m}\u001b[39;00m\u001b[38;5;124m is not a local folder and is not a valid model identifier \u001b[39m\u001b[38;5;124m\"\u001b[39m\n\u001b[0;32m    428\u001b[0m         \u001b[38;5;124m\"\u001b[39m\u001b[38;5;124mlisted on \u001b[39m\u001b[38;5;124m'\u001b[39m\u001b[38;5;124mhttps://huggingface.co/models\u001b[39m\u001b[38;5;124m'\u001b[39m\u001b[38;5;130;01m\\n\u001b[39;00m\u001b[38;5;124mIf this is a private repository, make sure to pass a token \u001b[39m\u001b[38;5;124m\"\u001b[39m\n\u001b[0;32m    429\u001b[0m         \u001b[38;5;124m\"\u001b[39m\u001b[38;5;124mhaving permission to this repo either by logging in with `huggingface-cli login` or by passing \u001b[39m\u001b[38;5;124m\"\u001b[39m\n\u001b[0;32m    430\u001b[0m         \u001b[38;5;124m\"\u001b[39m\u001b[38;5;124m`token=<your_token>`\u001b[39m\u001b[38;5;124m\"\u001b[39m\n\u001b[0;32m    431\u001b[0m     ) \u001b[38;5;28;01mfrom\u001b[39;00m \u001b[38;5;21;01me\u001b[39;00m\n\u001b[0;32m    432\u001b[0m \u001b[38;5;28;01mexcept\u001b[39;00m RevisionNotFoundError \u001b[38;5;28;01mas\u001b[39;00m e:\n\u001b[0;32m    433\u001b[0m     \u001b[38;5;28;01mraise\u001b[39;00m \u001b[38;5;167;01mEnvironmentError\u001b[39;00m(\n\u001b[0;32m    434\u001b[0m         \u001b[38;5;124mf\u001b[39m\u001b[38;5;124m\"\u001b[39m\u001b[38;5;132;01m{\u001b[39;00mrevision\u001b[38;5;132;01m}\u001b[39;00m\u001b[38;5;124m is not a valid git identifier (branch name, tag name or commit id) that exists \u001b[39m\u001b[38;5;124m\"\u001b[39m\n\u001b[0;32m    435\u001b[0m         \u001b[38;5;124m\"\u001b[39m\u001b[38;5;124mfor this model name. Check the model page at \u001b[39m\u001b[38;5;124m\"\u001b[39m\n\u001b[0;32m    436\u001b[0m         \u001b[38;5;124mf\u001b[39m\u001b[38;5;124m\"\u001b[39m\u001b[38;5;124m'\u001b[39m\u001b[38;5;124mhttps://huggingface.co/\u001b[39m\u001b[38;5;132;01m{\u001b[39;00mpath_or_repo_id\u001b[38;5;132;01m}\u001b[39;00m\u001b[38;5;124m'\u001b[39m\u001b[38;5;124m for available revisions.\u001b[39m\u001b[38;5;124m\"\u001b[39m\n\u001b[0;32m    437\u001b[0m     ) \u001b[38;5;28;01mfrom\u001b[39;00m \u001b[38;5;21;01me\u001b[39;00m\n",
      "\u001b[1;31mOSError\u001b[0m: INSAIT/bgGPT is not a local folder and is not a valid model identifier listed on 'https://huggingface.co/models'\nIf this is a private repository, make sure to pass a token having permission to this repo either by logging in with `huggingface-cli login` or by passing `token=<your_token>`"
     ]
    }
   ],
   "source": [
    "# Зареждане на токенизатора и модела\n",
    "tokenizer = AutoTokenizer.from_pretrained(\"INSAIT/bgGPT\")\n",
    "model = AutoModel.from_pretrained(\"INSAIT/bgGPT\")"
   ]
  },
  {
   "cell_type": "code",
   "execution_count": null,
   "id": "fcab03b9",
   "metadata": {},
   "outputs": [],
   "source": [
    "# Път до директорията с текстовите файлове\n",
    "directory = \"path/to/your/files/\""
   ]
  },
  {
   "cell_type": "code",
   "execution_count": null,
   "id": "40812cbd",
   "metadata": {},
   "outputs": [],
   "source": [
    "# Функция за четене на текстови файлове\n",
    "def read_files(directory):\n",
    "    texts = []\n",
    "    for filename in os.listdir(directory):\n",
    "        if filename.endswith(\".txt\"):\n",
    "            with open(os.path.join(directory, filename), 'r', encoding='utf-8') as file:\n",
    "                texts.append(file.read().strip())\n",
    "    return texts"
   ]
  },
  {
   "cell_type": "code",
   "execution_count": null,
   "id": "83c38381",
   "metadata": {},
   "outputs": [],
   "source": [
    "# Четене на текстовите файлове\n",
    "texts = read_files(directory)"
   ]
  },
  {
   "cell_type": "code",
   "execution_count": null,
   "id": "0305b80e",
   "metadata": {},
   "outputs": [],
   "source": [
    "# Токенизиране на текста\n",
    "inputs = tokenizer(texts, padding=True, truncation=True, return_tensors='pt')\n"
   ]
  },
  {
   "cell_type": "code",
   "execution_count": null,
   "id": "0fa7fb9c",
   "metadata": {},
   "outputs": [],
   "source": [
    "# Генериране на embeddings\n",
    "with torch.no_grad():\n",
    "    outputs = model(**inputs)\n",
    "    embeddings = outputs.last_hidden_state[:, 0, :]  # Вземане на последния скрит слой за всеки текст\n"
   ]
  },
  {
   "cell_type": "code",
   "execution_count": null,
   "id": "7582bfd6",
   "metadata": {},
   "outputs": [],
   "source": [
    "# Преглед на embeddings\n",
    "for i, embedding in enumerate(embeddings):\n",
    "    print(f\"Embedding за файл '{texts[i]}':\\n{embedding}\\n\")"
   ]
  }
 ],
 "metadata": {
  "kernelspec": {
   "display_name": "Python 3 (ipykernel)",
   "language": "python",
   "name": "python3"
  },
  "language_info": {
   "codemirror_mode": {
    "name": "ipython",
    "version": 3
   },
   "file_extension": ".py",
   "mimetype": "text/x-python",
   "name": "python",
   "nbconvert_exporter": "python",
   "pygments_lexer": "ipython3",
   "version": "3.11.7"
  }
 },
 "nbformat": 4,
 "nbformat_minor": 5
}
